<?xml version="1.0" ?>
<!-- =================================================================================== -->
<!-- |    This document was autogenerated by xacro from /mnt/workspace/ros2_work/turtlebot3_ws/src/self_driving_bicycle/urdf/bicycle_drive.xacro.urdf | -->
<!-- |    EDITING THIS FILE BY HAND IS NOT RECOMMENDED                                 | -->
<!-- =================================================================================== -->
<robot name="bicycle_drive">
  <material name="white">
    <color rgba="1 1 1 1"/>
  </material>
  <material name="cyan">
    <color rgba="0.18 0.83 0.78 1"/>
  </material>
  <material name="blue">
    <color rgba="0.2 0.2 1 1"/>
  </material>
  <material name="black">
    <color rgba="0 0 0 1"/>
  </material>
  <material name="red">
    <color rgba="1 0 0 1"/>
  </material>
  <!-- <xacro:include filename="lidar.xacro" /> -->
  <!-- BASE LINK -->
  <link name="base_footprint"/>
  <!-- BASE FOOTPRINT LINK -->
  
    base_linkはタイヤの中央
    
  <joint name="base_footprint_joint" type="fixed">
    <parent link="base_footprint"/>
    <child link="base_link"/>
    <origin rpy="0 0 0" xyz="0 0 0.33"/>
  </joint>
  <link name="base_link"/>
  <!-- FRAME LINK -->
  <joint name="base_frame_joint" type="fixed">
    <parent link="base_link"/>
    <child link="frame"/>
    <origin rpy="0 0 0" xyz="0 0 0.495"/>
  </joint>
  <link name="frame">
    <visual>
      <origin rpy="0 1.5707963267948966 0" xyz="0 0 0"/>
      <geometry>
        <cylinder length="0.98" radius="0.01"/>
      </geometry>
      <material name="cyan"/>
    </visual>
    <collision>
      <origin rpy="0 1.5707963267948966 0" xyz="0 0 0"/>
      <geometry>
        <cylinder length="0.98" radius="0.01"/>
      </geometry>
    </collision>
    <inertial>
      <origin rpy="0 1.5707963267948966 0" xyz="0 0 0"/>
      <mass value="5.0"/>
      <inertia ixx="0.4002916666666666" ixy="0.0" ixz="0.0" iyy="0.4002916666666666" iyz="0.0" izz="0.00025"/>
    </inertial>
  </link>
  <gazebo reference="frame">
    <material>Gazebo/Turquoise</material>
  </gazebo>
  <!-- STEERING LINK -->
  <joint name="steering_joint" type="revolute">
    <axis xyz="0 0 1"/>
    <parent link="base_link"/>
    <child link="steering_link"/>
    <origin rpy="0 0 0" xyz="0.49 0 0"/>
    <limit effort="1e6" lower="-1.5707963267948966" upper="1.5707963267948966" velocity="1.5707963267948966"/>
  </joint>
  <link name="steering_link">
    <visual>
      <origin rpy="0 0 0" xyz="0 0 0.35"/>
      <geometry>
        <cylinder length="0.7" radius="0.01"/>
      </geometry>
      <material name="white"/>
    </visual>
    <collision>
      <origin rpy="0 0 0" xyz="0 0 0.35"/>
      <geometry>
        <cylinder length="0.7" radius="0.01"/>
      </geometry>
    </collision>
    <inertial>
      <origin rpy="0 0 0" xyz="0 0 0.35"/>
      <mass value="1.0"/>
      <inertia ixx="0.04085833333333333" ixy="0.0" ixz="0.0" iyy="0.04085833333333333" iyz="0.0" izz="5e-05"/>
    </inertial>
  </link>
  <gazebo reference="steering_link">
    <material>Gazebo/Turquoise</material>
  </gazebo>
  <joint name="back_pole_joint" type="fixed">
    <axis xyz="0 0 1"/>
    <parent link="base_link"/>
    <child link="back_pole_link"/>
    <origin rpy="0 0 0" xyz="-0.49 0 0"/>
  </joint>
  <link name="back_pole_link">
    <visual>
      <origin rpy="0 0 0" xyz="0 0 0.25"/>
      <geometry>
        <cylinder length="0.5" radius="0.01"/>
      </geometry>
      <material name="white"/>
    </visual>
    <collision>
      <origin rpy="0 0 0" xyz="0 0 0.25"/>
      <geometry>
        <cylinder length="0.5" radius="0.01"/>
      </geometry>
    </collision>
    <inertial>
      <origin rpy="0 0 0" xyz="0 0 0.35"/>
      <mass value="1.0"/>
      <inertia ixx="0.020858333333333333" ixy="0.0" ixz="0.0" iyy="0.020858333333333333" iyz="0.0" izz="5e-05"/>
    </inertial>
  </link>
  <gazebo reference="back_pole_link">
    <material>Gazebo/Turquoise</material>
  </gazebo>
  <joint name="handle_joint" type="fixed">
    <axis xyz="0 0 1"/>
    <parent link="steering_link"/>
    <child link="handle_link"/>
    <origin rpy="0 0 0" xyz="0 0 0.7"/>
  </joint>
  <link name="handle_link">
    <visual>
      <origin rpy="1.57 0 0" xyz="0 0 0"/>
      <geometry>
        <cylinder length="0.5" radius="0.01"/>
      </geometry>
      <material name="white"/>
    </visual>
    <collision>
      <origin rpy="1.57 0 0" xyz="0 0 0"/>
      <geometry>
        <cylinder length="0.5" radius="0.01"/>
      </geometry>
    </collision>
    <inertial>
      <origin rpy="1.57 0 0" xyz="0 0 0"/>
      <mass value="1.0"/>
      <inertia ixx="0.020858333333333333" ixy="0.0" ixz="0.0" iyy="0.020858333333333333" iyz="0.0" izz="5e-05"/>
    </inertial>
  </link>
  <gazebo reference="handle_link">
    <material>Gazebo/Turquoise</material>
  </gazebo>
  <!-- FRONT WHEEL -->
  <joint name="front_wheel_joint" type="continuous">
    <axis xyz="0 0 1"/>
    <parent link="steering_link"/>
    <child link="front_wheel"/>
    <origin rpy="1.57 0 0" xyz="0 0 0"/>
    <limit effort="1e6" velocity="10.0"/>
  </joint>
  <link name="front_wheel">
    <visual>
      <origin rpy="0 0 0" xyz="0 0 0"/>
      <geometry>
        <cylinder length="0.0005" radius="0.33"/>
      </geometry>
      <material name="black"/>
    </visual>
    <collision>
      <origin rpy="0 0 0" xyz="0 0 0"/>
      <geometry>
        <cylinder length="0.0005" radius="0.33"/>
      </geometry>
    </collision>
    <inertial>
      <origin rpy="0 0 0" xyz="0 0 0"/>
      <mass value="1.2"/>
      <inertia ixx="0.03267002499999999" ixy="0.0" ixz="0.0" iyy="0.03267002499999999" iyz="0.0" izz="0.06534000000000001"/>
    </inertial>
  </link>
  <gazebo reference="front_wheel">
    <material>Gazebo/Grey</material>
    <mu1 value="0.5"/>
    <mu2 value="0.5"/>
  </gazebo>
  <!-- BACK OR TRACTION WHEEL -->
  <joint name="back_wheel_joint" type="continuous">
    <axis xyz="0 0 1"/>
    <parent link="base_link"/>
    <child link="back_wheel"/>
    <origin rpy="1.57 0 0" xyz="-0.49 0 0"/>
    <limit effort="1e6" velocity="10.0"/>
  </joint>
  <link name="back_wheel">
    <visual>
      <origin rpy="0 0 0" xyz="0 0 0"/>
      <geometry>
        <cylinder length="0.0005" radius="0.33"/>
      </geometry>
      <material name="black"/>
    </visual>
    <collision>
      <origin rpy="0 0 0" xyz="0 0 0"/>
      <geometry>
        <cylinder length="0.0005" radius="0.33"/>
      </geometry>
    </collision>
    <inertial>
      <origin rpy="0 0 0" xyz="0 0 0"/>
      <mass value="1.2"/>
      <inertia ixx="0.03267002499999999" ixy="0.0" ixz="0.0" iyy="0.03267002499999999" iyz="0.0" izz="0.06534000000000001"/>
    </inertial>
  </link>
  <gazebo reference="back_wheel">
    <material>Gazebo/Grey</material>
    <mu1 value="0.5"/>
    <mu2 value="0.5"/>
  </gazebo>
  <joint name="front_wheel_accent_joint" type="fixed">
    <axis xyz="0 0 1"/>
    <parent link="front_wheel"/>
    <child link="front_wheel_accent"/>
    <origin rpy="0 0 0" xyz="0 0 0"/>
  </joint>
  <link name="front_wheel_accent">
    <visual>
      <origin rpy="1.5707963267948966 0 0" xyz="0 0.165 0"/>
      <geometry>
        <cylinder length="0.33" radius="0.002"/>
      </geometry>
      <material name="white"/>
    </visual>
  </link>
  <gazebo reference="front_wheel_accent">
    <material>Gazebo/White</material>
  </gazebo>
  <joint name="back_wheel_accent_joint" type="fixed">
    <axis xyz="0 0 1"/>
    <parent link="back_wheel"/>
    <child link="back_wheel_accent"/>
    <origin rpy="0 0 0" xyz="0 0 0"/>
  </joint>
  <link name="back_wheel_accent">
    <visual>
      <origin rpy="1.5707963267948966 0 0" xyz="0 0.165 0"/>
      <geometry>
        <cylinder length="0.33" radius="0.002"/>
      </geometry>
      <material name="white"/>
    </visual>
  </link>
  <gazebo reference="back_wheel_accent">
    <material>Gazebo/White</material>
  </gazebo>
  <!-- <xacro:include filename="ros2_control.xacro" /> -->
</robot>
